<?xml version="1.0" ?>
<!-- =================================================================================== -->
<!-- |    This document was autogenerated by xacro from /home/esparza/ROS2_nivel2/ros2_ws_lvl2/src/my_robot_description/urdf/my_robot.urdf.xacro | -->
<!-- |    EDITING THIS FILE BY HAND IS NOT RECOMMENDED                                 | -->
<!-- =================================================================================== -->
<robot name="my_robot">
  <material name="blue">
    <color rgba="0 0 0.5 1"/>
  </material>
  <material name="grey">
    <color rgba="0.5 0.5 0.5 1"/>
  </material>
  <material name="orange">
    <color rgba="1 0.5 0 1"/>
  </material>
  <material name="yellow">
    <color rgba="1 1 0 1"/>
  </material>
  <link name="arm_base_link">
    <visual>
      <geometry>
        <box size="0.1 0.1 0.02"/>
      </geometry>
      <origin rpy="0 0 0" xyz="0 0 0.01"/>
      <material name="orange"/>
    </visual>
    <collision>
      <geometry>
        <box size="0.1 0.1 0.02"/>
      </geometry>
      <origin rpy="0 0 0" xyz="0 0 0.01"/>
    </collision>
    <inertial>
      <origin rpy="0 0 0" xyz="0 0 0.01"/>
      <mass value="0.5"/>
      <inertia ixx="0.00043333333333333337" ixy="0" ixz="0" iyy="0.0008333333333333335" iyz="0" izz="0.00043333333333333337"/>
    </inertial>
  </link>
  <link name="forearm_link">
    <visual>
      <geometry>
        <cylinder length="0.3" radius="0.02"/>
      </geometry>
      <origin rpy="0 0 0" xyz="0 0 0.15"/>
      <material name="yellow"/>
    </visual>
    <collision>
      <geometry>
        <cylinder length="0.3" radius="0.02"/>
      </geometry>
      <origin rpy="0 0 0" xyz="0 0 0.15"/>
    </collision>
    <inertial>
      <origin rpy="0 0 0" xyz="0 0 0.15"/>
      <mass value="0.3"/>
      <inertia ixx="0.00228" ixy="0" ixz="0" iyy="0.00228" iyz="0" izz="6e-05"/>
    </inertial>
  </link>
  <link name="hand_link">
    <visual>
      <geometry>
        <cylinder length="0.3" radius="0.02"/>
      </geometry>
      <origin rpy="0 0 0" xyz="0 0 0.15"/>
      <material name="orange"/>
    </visual>
    <collision>
      <geometry>
        <cylinder length="0.3" radius="0.02"/>
      </geometry>
      <origin rpy="0 0 0" xyz="0 0 0.15"/>
    </collision>
    <inertial>
      <origin rpy="0 0 0" xyz="0 0 0.15"/>
      <mass value="0.3"/>
      <inertia ixx="0.00228" ixy="0" ixz="0" iyy="0.00228" iyz="0" izz="6e-05"/>
    </inertial>
  </link>
  <joint name="arm_base_forearm_joint" type="revolute">
    <parent link="arm_base_link"/>
    <child link="forearm_link"/>
    <origin rpy="0 0 0" xyz="0 0 0.02"/>
    <limit effort="100" lower="0" upper="1.5707963267948966" velocity="100"/>
    <dynamics damping="0.1" friction="0.05"/>
  </joint>
  <joint name="forearm_hand_joint" type="revolute">
    <parent link="forearm_link"/>
    <child link="hand_link"/>
    <origin rpy="0 0 0" xyz="0 0 0.3"/>
    <limit effort="100" lower="0" upper="1.5707963267948966" velocity="100"/>
    <dynamics damping="0.1" friction="0.05"/>
  </joint>
  <link name="base_link">
    <visual>
      <geometry>
        <box size="0.6 0.4 0.2"/>
      </geometry>
      <origin rpy="0 0 0" xyz="0 0 0.1"/>
      <material name="blue"/>
    </visual>
    <collision>
      <geometry>
        <box size="0.6 0.4 0.2"/>
      </geometry>
      <origin rpy="0 0 0" xyz="0 0 0.1"/>
    </collision>
    <inertial>
      <origin rpy="0 0 0" xyz="0 0 0.1"/>
      <mass value="5.0"/>
      <inertia ixx="0.6666666666666667" ixy="0" ixz="0" iyy="0.8666666666666667" iyz="0" izz="0.3333333333333334"/>
    </inertial>
  </link>
  <link name="left_wheel_link">
    <visual>
      <geometry>
        <cylinder length="0.05" radius="0.1"/>
      </geometry>
      <origin rpy="1.5707963267948966 0 0" xyz="0 0 0"/>
      <material name="grey"/>
    </visual>
    <collision>
      <geometry>
        <cylinder length="0.05" radius="0.1"/>
      </geometry>
      <origin rpy="1.5707963267948966 0 0" xyz="0 0 0"/>
    </collision>
    <inertial>
      <origin rpy="1.5707963267948966 0 0" xyz="0 0 0"/>
      <mass value="1.0"/>
      <inertia ixx="0.010833333333333335" ixy="0" ixz="0" iyy="0.010833333333333335" iyz="0" izz="0.020000000000000004"/>
    </inertial>
  </link>
  <link name="right_wheel_link">
    <visual>
      <geometry>
        <cylinder length="0.05" radius="0.1"/>
      </geometry>
      <origin rpy="1.5707963267948966 0 0" xyz="0 0 0"/>
      <material name="grey"/>
    </visual>
    <collision>
      <geometry>
        <cylinder length="0.05" radius="0.1"/>
      </geometry>
      <origin rpy="1.5707963267948966 0 0" xyz="0 0 0"/>
    </collision>
    <inertial>
      <origin rpy="1.5707963267948966 0 0" xyz="0 0 0"/>
      <mass value="1.0"/>
      <inertia ixx="0.010833333333333335" ixy="0" ixz="0" iyy="0.010833333333333335" iyz="0" izz="0.020000000000000004"/>
    </inertial>
  </link>
  <link name="caster_wheel_link">
    <visual>
      <geometry>
        <sphere radius="0.05"/>
      </geometry>
      <origin rpy="0 0 0" xyz="0 0 0"/>
      <material name="grey"/>
    </visual>
    <collision>
      <geometry>
        <sphere radius="0.05"/>
      </geometry>
      <origin rpy="0 0 0" xyz="0 0 0"/>
      <surface>
        <friction>
          <ode>
            <mu>0.1</mu>
            <mu2>0.1</mu2>
          </ode>
        </friction>
      </surface>
    </collision>
    <inertial>
      <origin rpy="0 0 0" xyz="0 0 0"/>
      <mass value="0.5"/>
      <inertia ixx="0.0020000000000000005" ixy="0" ixz="0" iyy="0.0020000000000000005" iyz="0" izz="0.0020000000000000005"/>
    </inertial>
  </link>
  <link name="base_footprint"/>
  <joint name="base_right_wheel_joint" type="continuous">
    <parent link="base_link"/>
    <child link="right_wheel_link"/>
    <origin rpy="0 0 0" xyz="-0.15 -0.225 0"/>
    <axis xyz="0 1 0"/>
  </joint>
  <joint name="base_left_wheel_joint" type="continuous">
    <parent link="base_link"/>
    <child link="left_wheel_link"/>
    <origin rpy="0 0 0" xyz="-0.15 0.225 0"/>
    <axis xyz="0 1 0"/>
  </joint>
  <joint name="base_caster_wheel_joint" type="fixed">
    <parent link="base_link"/>
    <child link="caster_wheel_link"/>
    <origin rpy="0 0 0" xyz="0.19999999999999998 0 -0.05"/>
  </joint>
  <joint name="base_joint" type="fixed">
    <parent link="base_footprint"/>
    <child link="base_link"/>
    <origin rpy="0 0 0" xyz="0 0 0.1"/>
  </joint>
  <joint name="mobile_base_arm_base_joint" type="fixed">
    <parent link="base_link"/>
    <child link="arm_base_link"/>
    <origin rpy="0 0 1.5707963267948966" xyz="0.17142857142857143 0 0.2"/>
  </joint>
  <link name="camera_link">
    <visual>
      <geometry>
        <box size="0.01 0.1 0.05"/>
      </geometry>
      <material name="grey"/>
    </visual>
    <collision>
      <geometry>
        <box size="0.01 0.1 0.05"/>
      </geometry>
    </collision>
    <inertial>
      <origin rpy="0 0 0" xyz="0 0 0"/>
      <mass value="0.1"/>
      <inertia ixx="2.166666666666667e-05" ixy="0" ixz="0" iyy="8.416666666666668e-05" iyz="0" izz="0.00010416666666666669"/>
    </inertial>
  </link>
  <joint name="base_camera_joint" type="fixed">
    <parent link="base_link"/>
    <child link="camera_link"/>
    <origin rpy="0 0 0" xyz="0.305 0 0.1"/>
  </joint>
</robot>
