<?xml version="1.0" ?>
<!-- =================================================================================== -->
<!-- |    This document was autogenerated by xacro from /home/esparza/ROS2_nivel2/ros2_ws_lvl2/src/my_robot_description/urdf/standalone_arm.xacro | -->
<!-- |    EDITING THIS FILE BY HAND IS NOT RECOMMENDED                                 | -->
<!-- =================================================================================== -->
<robot name="my_robot_arm">
  <material name="blue">
    <color rgba="0 0 0.5 1"/>
  </material>
  <material name="grey">
    <color rgba="0.5 0.5 0.5 1"/>
  </material>
  <material name="orange">
    <color rgba="1 0.5 0 1"/>
  </material>
  <material name="yellow">
    <color rgba="1 1 0 1"/>
  </material>
  <link name="arm_base_link">
    <visual>
      <geometry>
        <box size="0.1 0.1 0.02"/>
      </geometry>
      <origin rpy="0 0 0" xyz="0 0 0.01"/>
      <material name="orange"/>
    </visual>
    <collision>
      <geometry>
        <box size="0.1 0.1 0.02"/>
      </geometry>
      <origin rpy="0 0 0" xyz="0 0 0.01"/>
    </collision>
    <inertial>
      <origin rpy="0 0 0" xyz="0 0 0.01"/>
      <mass value="0.5"/>
      <inertia ixx="0.00043333333333333337" ixy="0" ixz="0" iyy="0.0008333333333333335" iyz="0" izz="0.00043333333333333337"/>
    </inertial>
  </link>
  <link name="forearm_link">
    <visual>
      <geometry>
        <cylinder length="0.3" radius="0.02"/>
      </geometry>
      <origin rpy="0 0 0" xyz="0 0 0.15"/>
      <material name="yellow"/>
    </visual>
    <collision>
      <geometry>
        <cylinder length="0.3" radius="0.02"/>
      </geometry>
      <origin rpy="0 0 0" xyz="0 0 0.15"/>
    </collision>
    <inertial>
      <origin rpy="0 0 0" xyz="0 0 0.15"/>
      <mass value="0.3"/>
      <inertia ixx="0.00228" ixy="0" ixz="0" iyy="0.00228" iyz="0" izz="6e-05"/>
    </inertial>
  </link>
  <link name="hand_link">
    <visual>
      <geometry>
        <cylinder length="0.3" radius="0.02"/>
      </geometry>
      <origin rpy="0 0 0" xyz="0 0 0.15"/>
      <material name="orange"/>
    </visual>
    <collision>
      <geometry>
        <cylinder length="0.3" radius="0.02"/>
      </geometry>
      <origin rpy="0 0 0" xyz="0 0 0.15"/>
    </collision>
    <inertial>
      <origin rpy="0 0 0" xyz="0 0 0.15"/>
      <mass value="0.3"/>
      <inertia ixx="0.00228" ixy="0" ixz="0" iyy="0.00228" iyz="0" izz="6e-05"/>
    </inertial>
  </link>
  <joint name="arm_base_forearm_joint" type="revolute">
    <parent link="arm_base_link"/>
    <child link="forearm_link"/>
    <origin rpy="0 0 0" xyz="0 0 0.02"/>
    <limit effort="100" lower="0" upper="1.5707963267948966" velocity="100"/>
  </joint>
  <joint name="forearm_hand_joint" type="revolute">
    <parent link="forearm_link"/>
    <child link="hand_link"/>
    <origin rpy="0 0 0" xyz="0 0 0.3"/>
    <limit effort="100" lower="0" upper="1.5707963267948966" velocity="100"/>
  </joint>
</robot>
