<?xml version="1.0"?>
<sdf version='1.9'>
  <world name='my_robot_world'>
    <physics name='1ms' type='ignored'>
      <max_step_size>0.001</max_step_size>
      <real_time_factor>1</real_time_factor>
      <real_time_update_rate>1000</real_time_update_rate>
    </physics>
    <plugin name='gz::sim::systems::Physics' filename='ignition-gazebo-physics-system'/>
    <plugin name='gz::sim::systems::UserCommands' filename='ignition-gazebo-user-commands-system'/>
    <plugin name='gz::sim::systems::SceneBroadcaster' filename='ignition-gazebo-scene-broadcaster-system'/>
    <plugin name='gz::sim::systems::Contact' filename='ignition-gazebo-contact-system'/>
    <gravity>0 0 -9.8</gravity>
    <magnetic_field>6e-06 2.3e-05 -4.2e-05</magnetic_field>
    <atmosphere type='adiabatic'/>
    <scene>
      <ambient>0.4 0.4 0.4 1</ambient>
      <background>0.7 0.7 0.7 1</background>
      <shadows>true</shadows>
    </scene>
    <!-- Keyboard movement -->
    <plugin name='ignition::gazebo::systems::TriggeredPublisher' filename='libignition-gazebo-triggered-publisher-system.so'>
      <input type='ignition.msgs.Int32' topic='/keyboard/keypress'>
        <match field='data'>16777235</match><!-- Up -->
      </input>
      <output type='ignition.msgs.Twist' topic='/cmd_vel'>linear: {x: 0.5}, angular: {z: 0.0}</output>
    </plugin>
    <plugin name='ignition::gazebo::systems::TriggeredPublisher' filename='libignition-gazebo-triggered-publisher-system.so'>
      <input type='ignition.msgs.Int32' topic='/keyboard/keypress'>
        <match field='data'>16777237</match><!-- Down -->
      </input>
      <output type='ignition.msgs.Twist' topic='/cmd_vel'>linear: {x: -0.5}, angular: {z: 0.0}</output>
    </plugin>
    <plugin name='ignition::gazebo::systems::TriggeredPublisher' filename='libignition-gazebo-triggered-publisher-system.so'>
      <input type='ignition.msgs.Int32' topic='/keyboard/keypress'>
        <match field='data'>16777234</match><!-- Left -->
      </input>
      <output type='ignition.msgs.Twist' topic='/cmd_vel'>linear: {x: 0.0}, angular: {z: 0.5}</output>
    </plugin>
    <plugin name='ignition::gazebo::systems::TriggeredPublisher' filename='libignition-gazebo-triggered-publisher-system.so'>
      <input type='ignition.msgs.Int32' topic='/keyboard/keypress'>
        <match field='data'>16777236</match><!-- Right -->
      </input>
      <output type='ignition.msgs.Twist' topic='/cmd_vel'>linear: {x: 0.0}, angular: {z: -0.5}</output>
    </plugin>
    <plugin name='ignition::gazebo::systems::TriggeredPublisher' filename='libignition-gazebo-triggered-publisher-system.so'>
      <input type='ignition.msgs.Int32' topic='/keyboard/keypress'>
        <match field='data'>48</match><!-- Stop -->
      </input>
      <output type='ignition.msgs.Twist' topic='/cmd_vel'>linear: {x: 0.0}, angular: {z: 0.0}</output>
    </plugin>
    <plugin name='ignition::gazebo::systems::TriggeredPublisher' filename='libignition-gazebo-triggered-publisher-system.so'>
      <input type='ignition.msgs.Int32' topic='/keyboard/keypress'>
        <match field='data'>16777221</match><!-- Reset arm intro numpad -->
      </input>
      <output type='ignition.msgs.Double' topic='/model/urdf_model/joint/arm_base_forearm_joint/0/cmd_pos'>data: 0.0</output>
      <output type='ignition.msgs.Double' topic='/model/urdf_model/joint/forearm_hand_joint/0/cmd_pos'>data: 0.0</output>
    </plugin>
    <model name='ground_plane'>
      <static>true</static>
      <link name='link'>
        <collision name='collision'>
          <geometry>
            <plane>
              <normal>0 0 1</normal>
              <size>100 100</size>
            </plane>
          </geometry>
          <surface>
            <friction>
              <ode/>
            </friction>
            <bounce/>
            <contact/>
          </surface>
        </collision>
        <visual name='visual'>
          <geometry>
            <plane>
              <normal>0 0 1</normal>
              <size>100 100</size>
            </plane>
          </geometry>
          <material>
            <ambient>0.8 0.8 0.8 1</ambient>
            <diffuse>0.8 0.8 0.8 1</diffuse>
            <specular>0.8 0.8 0.8 1</specular>
          </material>
        </visual>
        <pose>0 0 0 0 -0 0</pose>
        <inertial>
          <pose>0 0 0 0 -0 0</pose>
          <mass>1</mass>
          <inertia>
            <ixx>1</ixx>
            <ixy>0</ixy>
            <ixz>0</ixz>
            <iyy>1</iyy>
            <iyz>0</iyz>
            <izz>1</izz>
          </inertia>
        </inertial>
        <enable_wind>false</enable_wind>
      </link>
      <pose>0 0 0 0 -0 0</pose>
      <self_collide>false</self_collide>
    </model>
    <model name='urdf_model'>
      <link name='base_footprint'>
        <inertial>
          <pose>0.035445 0 0.196721 0 -0 0</pose>
          <mass>6.0999999999999996</mass>
          <inertia>
            <ixx>0.68675600000000003</ixx>
            <ixy>-1.13311e-19</ixy>
            <ixz>0.0048625300000000003</ixz>
            <iyy>0.92275099999999999</iyy>
            <iyz>0</iyz>
            <izz>0.37220399999999998</izz>
          </inertia>
        </inertial>
        <collision name='base_footprint_fixed_joint_lump__base_link_collision'>
          <pose>0 0 0.2 0 0 0</pose>
          <geometry>
            <box>
              <size>0.6 0.4 0.2</size>
            </box>
          </geometry>
          <surface>
            <friction>
              <ode/>
            </friction>
            <bounce/>
            <contact/>
          </surface>
        </collision>
        <collision name='base_footprint_fixed_joint_lump__camera_link_collision_1'>
          <pose>0.305 0 0.2 0 0 0</pose>
          <geometry>
            <box>
              <size>0.01 0.1 0.05</size>
            </box>
          </geometry>
          <surface>
            <friction>
              <ode/>
            </friction>
            <bounce/>
            <contact/>
          </surface>
        </collision>
        <collision name='base_footprint_fixed_joint_lump__caster_wheel_link_collision_2'>
          <pose>0.2 0 0.05 0 0 0</pose>
          <geometry>
            <sphere>
              <radius>0.050000000000000003</radius>
            </sphere>
          </geometry>
          <surface>
            <friction>
              <ode>
                <mu>0.1</mu>
                <mu2>0.1</mu2>
              </ode>
            </friction>
            <bounce/>
            <contact/>
          </surface>
        </collision>
        <collision name='base_footprint_fixed_joint_lump__arm_base_link_collision_3'>
          <pose>0.1714285714285714 0 0.3100000000000001 0 0 1.570796326794896</pose>
          <geometry>
            <box>
              <size>0.1 0.1 0.02</size>
            </box>
          </geometry>
          <surface>
            <friction>
              <ode/>
            </friction>
            <bounce/>
            <contact/>
          </surface>
        </collision>
        <visual name='base_footprint_fixed_joint_lump__base_link_visual'>
          <pose>0 0 0.2 0 0 0</pose>
          <geometry>
            <box>
              <size>0.6 0.4 0.2</size>
            </box>
          </geometry>
          <material>
            <diffuse>0 0 0.625 1</diffuse>
            <ambient>0 0 0.625 1</ambient>
          </material>
        </visual>
        <visual name='base_footprint_fixed_joint_lump__camera_link_visual_1'>
          <pose>0.305 0 0.2 0 0 0</pose>
          <geometry>
            <box>
              <size>0.01 0.1 0.05</size>
            </box>
          </geometry>
          <material>
            <diffuse>0.625 0.625 0.625 1</diffuse>
            <ambient>0.625 0.625 0.625 1</ambient>
          </material>
        </visual>
        <visual name='base_footprint_fixed_joint_lump__caster_wheel_link_visual_2'>
          <pose>0.2 0 0.05 0 0 0</pose>
          <geometry>
            <sphere>
              <radius>0.050000000000000003</radius>
            </sphere>
          </geometry>
          <material>
            <diffuse>0.625 0.625 0.625 1</diffuse>
            <ambient>0.625 0.625 0.625 1</ambient>
          </material>
        </visual>
        <visual name='base_footprint_fixed_joint_lump__arm_base_link_visual_3'>
          <pose>0.1714285714285714 0 0.3100000000000001 0 0 1.570796326794896</pose>
          <geometry>
            <box>
              <size>0.1 0.1 0.02</size>
            </box>
          </geometry>
          <material>
            <diffuse>1 0.625 0 1</diffuse>
            <ambient>1 0.625 0 1</ambient>
          </material>
        </visual>
        <pose>0 0 0 0 -0 0</pose>
        <enable_wind>false</enable_wind>
      </link>
      <joint name='base_left_wheel_joint' type='revolute'>
        <pose>0 0 0 0 -0 0</pose>
        <parent>base_footprint</parent>
        <child>left_wheel_link</child>
        <axis>
          <xyz>0 1 0</xyz>
          <limit>
            <lower>-10000000000000000</lower>
            <upper>10000000000000000</upper>
            <effort>inf</effort>
            <velocity>inf</velocity>
            <stiffness>100000000</stiffness>
            <dissipation>1</dissipation>
          </limit>
          <dynamics>
            <spring_reference>0</spring_reference>
            <spring_stiffness>0</spring_stiffness>
            <damping>0</damping>
            <friction>0</friction>
          </dynamics>
        </axis>
      </joint>
      <link name='left_wheel_link'>
        <pose>-0.15 0.225 0.1 -0 -0.059289 -0</pose>
        <inertial>
          <pose>0 0 0 1.5708 -0 0</pose>
          <mass>1</mass>
          <inertia>
            <ixx>0.010833300000000001</ixx>
            <ixy>0</ixy>
            <ixz>0</ixz>
            <iyy>0.010833300000000001</iyy>
            <iyz>0</iyz>
            <izz>0.02</izz>
          </inertia>
        </inertial>
        <collision name='left_wheel_link_collision'>
          <pose>0 0 0 1.570796326794896 0 0</pose>
          <geometry>
            <cylinder>
              <length>0.050000000000000003</length>
              <radius>0.10000000000000001</radius>
            </cylinder>
          </geometry>
          <surface>
            <friction>
              <ode/>
            </friction>
            <bounce/>
            <contact/>
          </surface>
        </collision>
        <visual name='left_wheel_link_visual'>
          <pose>0 0 0 1.570796326794896 0 0</pose>
          <geometry>
            <cylinder>
              <length>0.050000000000000003</length>
              <radius>0.10000000000000001</radius>
            </cylinder>
          </geometry>
          <material>
            <diffuse>0.625 0.625 0.625 1</diffuse>
            <ambient>0.625 0.625 0.625 1</ambient>
          </material>
        </visual>
        <enable_wind>false</enable_wind>
      </link>
      <joint name='base_right_wheel_joint' type='revolute'>
        <pose>0 0 0 0 -0 0</pose>
        <parent>base_footprint</parent>
        <child>right_wheel_link</child>
        <axis>
          <xyz>0 1 0</xyz>
          <limit>
            <lower>-10000000000000000</lower>
            <upper>10000000000000000</upper>
            <effort>inf</effort>
            <velocity>inf</velocity>
            <stiffness>100000000</stiffness>
            <dissipation>1</dissipation>
          </limit>
          <dynamics>
            <spring_reference>0</spring_reference>
            <spring_stiffness>0</spring_stiffness>
            <damping>0</damping>
            <friction>0</friction>
          </dynamics>
        </axis>
      </joint>
      <link name='right_wheel_link'>
        <pose>-0.15 -0.225 0.1 -0 -0.059289 -0</pose>
        <inertial>
          <pose>0 0 0 1.5708 -0 0</pose>
          <mass>1</mass>
          <inertia>
            <ixx>0.010833300000000001</ixx>
            <ixy>0</ixy>
            <ixz>0</ixz>
            <iyy>0.010833300000000001</iyy>
            <iyz>0</iyz>
            <izz>0.02</izz>
          </inertia>
        </inertial>
        <collision name='right_wheel_link_collision'>
          <pose>0 0 0 1.570796326794896 0 0</pose>
          <geometry>
            <cylinder>
              <length>0.050000000000000003</length>
              <radius>0.10000000000000001</radius>
            </cylinder>
          </geometry>
          <surface>
            <friction>
              <ode/>
            </friction>
            <bounce/>
            <contact/>
          </surface>
        </collision>
        <visual name='right_wheel_link_visual'>
          <pose>0 0 0 1.570796326794896 0 0</pose>
          <geometry>
            <cylinder>
              <length>0.050000000000000003</length>
              <radius>0.10000000000000001</radius>
            </cylinder>
          </geometry>
          <material>
            <diffuse>0.625 0.625 0.625 1</diffuse>
            <ambient>0.625 0.625 0.625 1</ambient>
          </material>
        </visual>
        <enable_wind>false</enable_wind>
      </link>
      <joint name='arm_base_forearm_joint' type='revolute'>
        <pose>0 -0 0 0 -0 0</pose>
        <parent>base_footprint</parent>
        <child>forearm_link</child>
        <axis>
          <xyz>1 0 0</xyz>
          <limit>
            <lower>0</lower>
            <upper>1.5708</upper>
            <effort>100</effort>
            <velocity>100</velocity>
            <stiffness>100000000</stiffness>
            <dissipation>1</dissipation>
          </limit>
          <dynamics>
            <spring_reference>0</spring_reference>
            <spring_stiffness>0</spring_stiffness>
            <damping>0.10000000000000001</damping>
            <friction>0.050000000000000003</friction>
          </dynamics>
        </axis>
      </joint>
      <plugin name='ignition::gazebo::systems::JointPositionController' filename='libignition-gazebo-joint-position-controller-system.so'>
        <joint_name>arm_base_forearm_joint</joint_name>
        <target>0</target>
      </plugin>
      <link name='forearm_link'>
        <pose>0.171429 0 0.32 -0 0 1.5708</pose>
        <inertial>
          <pose>0 0 0.15 0 -0 0</pose>
          <mass>0.29999999999999999</mass>
          <inertia>
            <ixx>0.0022799999999999999</ixx>
            <ixy>0</ixy>
            <ixz>0</ixz>
            <iyy>0.0022799999999999999</iyy>
            <iyz>0</iyz>
            <izz>6.0000000000000002e-05</izz>
          </inertia>
        </inertial>
        <collision name='forearm_link_collision'>
          <pose>0 0 0.15 0 0 0</pose>
          <geometry>
            <cylinder>
              <length>0.29999999999999999</length>
              <radius>0.02</radius>
            </cylinder>
          </geometry>
          <surface>
            <friction>
              <ode/>
            </friction>
            <bounce/>
            <contact/>
          </surface>
        </collision>
        <visual name='forearm_link_visual'>
          <pose>0 0 0.15 0 0 0</pose>
          <geometry>
            <cylinder>
              <length>0.29999999999999999</length>
              <radius>0.02</radius>
            </cylinder>
          </geometry>
          <material>
            <diffuse>1 1 0 1</diffuse>
            <ambient>1 1 0 1</ambient>
          </material>
        </visual>
        <enable_wind>false</enable_wind>
      </link>
      <joint name='forearm_hand_joint' type='revolute'>
        <pose>0 -0 0 0 -0 0</pose>
        <parent>forearm_link</parent>
        <child>hand_link</child>
        <axis>
          <xyz>1 0 0</xyz>
          <limit>
            <lower>0</lower>
            <upper>1.5708</upper>
            <effort>100</effort>
            <velocity>100</velocity>
            <stiffness>100000000</stiffness>
            <dissipation>1</dissipation>
          </limit>
          <dynamics>
            <spring_reference>0</spring_reference>
            <spring_stiffness>0</spring_stiffness>
            <damping>0.10000000000000001</damping>
            <friction>0.050000000000000003</friction>
          </dynamics>
        </axis>
      </joint>
      <plugin name='ignition::gazebo::systems::JointPositionController' filename='libignition-gazebo-joint-position-controller-system.so'>
        <joint_name>forearm_hand_joint</joint_name>
        <target>0</target>
      </plugin>
      <link name='hand_link'>
        <pose>0.171429 0 0.62 -0 0 1.5708</pose>
        <inertial>
          <pose>0 0 0.15 0 -0 0</pose>
          <mass>0.29999999999999999</mass>
          <inertia>
            <ixx>0.0022799999999999999</ixx>
            <ixy>0</ixy>
            <ixz>0</ixz>
            <iyy>0.0022799999999999999</iyy>
            <iyz>0</iyz>
            <izz>6.0000000000000002e-05</izz>
          </inertia>
        </inertial>
        <collision name='hand_link_collision'>
          <pose>0 0 0.15 0 0 0</pose>
          <geometry>
            <cylinder>
              <length>0.29999999999999999</length>
              <radius>0.02</radius>
            </cylinder>
          </geometry>
          <surface>
            <friction>
              <ode/>
            </friction>
            <bounce/>
            <contact/>
          </surface>
        </collision>
        <visual name='hand_link_visual'>
          <pose>0 0 0.15 0 0 0</pose>
          <geometry>
            <cylinder>
              <length>0.29999999999999999</length>
              <radius>0.02</radius>
            </cylinder>
          </geometry>
          <material>
            <diffuse>1 0.625 0 1</diffuse>
            <ambient>1 0.625 0 1</ambient>
          </material>
        </visual>
        <enable_wind>false</enable_wind>
      </link>
      <frame name='base_camera_joint' attached_to='base_link'>
        <pose>0.305 0 0.1 0 -0 0</pose>
      </frame>
      <frame name='camera_link' attached_to='base_camera_joint'/>
      <frame name='base_caster_wheel_joint' attached_to='base_link'>
        <pose>0.2 0 -0.05 0 -0 0</pose>
      </frame>
      <frame name='caster_wheel_link' attached_to='base_caster_wheel_joint'/>
      <frame name='mobile_base_arm_base_joint' attached_to='base_link'>
        <pose>0.171429 0 0.2 0 -0 1.5708</pose>
      </frame>
      <frame name='arm_base_link' attached_to='mobile_base_arm_base_joint'/>
      <frame name='base_joint' attached_to='base_footprint'>
        <pose>0 0 0.1 0 -0 0</pose>
      </frame>
      <frame name='base_link' attached_to='base_joint'/>
      <pose>-0.004507 -0 -0 0 1e-06 0</pose>
      <static>false</static>
      <self_collide>false</self_collide>
      <plugin filename="libignition-gazebo-diff-drive-system.so" name="ignition::gazebo::systems::DiffDrive">
        <left_joint>base_left_wheel_joint</left_joint>
        <right_joint>base_right_wheel_joint</right_joint>
        <wheel_separation>0.45</wheel_separation>
        <wheel_radius>0.1</wheel_radius>
        <odom_publish_frequency>1</odom_publish_frequency>
        <topic>cmd_vel</topic>
    </plugin>
    </model>
    <light name='sun' type='directional'>
      <pose>0 0 10 0 -0 0</pose>
      <cast_shadows>true</cast_shadows>
      <intensity>1</intensity>
      <direction>-0.5 0.1 -0.9</direction>
      <diffuse>0.8 0.8 0.8 1</diffuse>
      <specular>0.2 0.2 0.2 1</specular>
      <attenuation>
        <range>1000</range>
        <linear>0.01</linear>
        <constant>0.90000000000000002</constant>
        <quadratic>0.001</quadratic>
      </attenuation>
      <spot>
        <inner_angle>0</inner_angle>
        <outer_angle>0</outer_angle>
        <falloff>0</falloff>
      </spot>
    </light>
  </world>
</sdf>
